GpuFreq=control_disabled
Traceback (most recent call last):
  File "/home/hk-project-sustainebot/bm3844/code/LLaMA-Factory-RoboG-v2/src/llamafactory/launcher.py", line 180, in <module>
Traceback (most recent call last):
  File "/home/hk-project-sustainebot/bm3844/code/LLaMA-Factory-RoboG-v2/src/llamafactory/launcher.py", line 180, in <module>
Traceback (most recent call last):
  File "/home/hk-project-sustainebot/bm3844/code/LLaMA-Factory-RoboG-v2/src/llamafactory/launcher.py", line 180, in <module>
Traceback (most recent call last):
      File "/home/hk-project-sustainebot/bm3844/code/LLaMA-Factory-RoboG-v2/src/llamafactory/launcher.py", line 180, in <module>
run_exp()
  File "/home/hk-project-sustainebot/bm3844/code/LLaMA-Factory-RoboG-v2/src/llamafactory/train/tuner.py", line 127, in run_exp
    run_exp()
    run_exp()
        run_exp()  File "/home/hk-project-sustainebot/bm3844/code/LLaMA-Factory-RoboG-v2/src/llamafactory/train/tuner.py", line 127, in run_exp
args = read_args(args)

   File "/home/hk-project-sustainebot/bm3844/code/LLaMA-Factory-RoboG-v2/src/llamafactory/train/tuner.py", line 127, in run_exp
   File "/home/hk-project-sustainebot/bm3844/code/LLaMA-Factory-RoboG-v2/src/llamafactory/train/tuner.py", line 127, in run_exp
         ^^^^^^^    ^args = read_args(args)^
^^^^^^    
 args = read_args(args) 
   File "/home/hk-project-sustainebot/bm3844/code/LLaMA-Factory-RoboG-v2/src/llamafactory/train/tuner.py", line 111, in read_args
            ^ ^ ^ ^ ^ ^ ^     ^^^^args = read_args(args)^^^^
^^^^^^^^
    ^^if sys.argv[1].endswith(".yaml") or sys.argv[1].endswith(".yml"):^
  File "/home/hk-project-sustainebot/bm3844/code/LLaMA-Factory-RoboG-v2/src/llamafactory/train/tuner.py", line 111, in read_args
^^^ ^
     File "/home/hk-project-sustainebot/bm3844/code/LLaMA-Factory-RoboG-v2/src/llamafactory/train/tuner.py", line 111, in read_args
          ~~ ~~ ~~ ~~ ^^^    ^if sys.argv[1].endswith(".yaml") or sys.argv[1].endswith(".yml"):^

^^IndexError: ^    list index out of range
^if sys.argv[1].endswith(".yaml") or sys.argv[1].endswith(".yml"): 
 ^ ^  ^  ^ ~ ^~ ~^ ~ ~^ ~ ~^~~^~^~^
~^~
~~IndexError~  File "/home/hk-project-sustainebot/bm3844/code/LLaMA-Factory-RoboG-v2/src/llamafactory/train/tuner.py", line 111, in read_args
: ^^list index out of range^

IndexError: list index out of range
    if sys.argv[1].endswith(".yaml") or sys.argv[1].endswith(".yml"):
       ~~~~~~~~^^^
IndexError: list index out of range
E1022 01:08:51.406000 3675904 /hkfs/home/project/hk-project-sustainebot/bm3844/miniconda3/envs/roboG_train/lib/python3.12/site-packages/torch/distributed/elastic/multiprocessing/api.py:874] failed (exitcode: 1) local_rank: 0 (pid: 3675906) of binary: /home/hk-project-sustainebot/bm3844/miniconda3/envs/roboG_train/bin/python3.12
Traceback (most recent call last):
  File "/home/hk-project-sustainebot/bm3844/miniconda3/envs/roboG_train/bin/torchrun", line 7, in <module>
    sys.exit(main())
             ^^^^^^
  File "/home/hk-project-sustainebot/bm3844/miniconda3/envs/roboG_train/lib/python3.12/site-packages/torch/distributed/elastic/multiprocessing/errors/__init__.py", line 357, in wrapper
    return f(*args, **kwargs)
           ^^^^^^^^^^^^^^^^^^
  File "/home/hk-project-sustainebot/bm3844/miniconda3/envs/roboG_train/lib/python3.12/site-packages/torch/distributed/run.py", line 901, in main
    run(args)
  File "/home/hk-project-sustainebot/bm3844/miniconda3/envs/roboG_train/lib/python3.12/site-packages/torch/distributed/run.py", line 892, in run
    elastic_launch(
  File "/home/hk-project-sustainebot/bm3844/miniconda3/envs/roboG_train/lib/python3.12/site-packages/torch/distributed/launcher/api.py", line 143, in __call__
    return launch_agent(self._config, self._entrypoint, list(args))
           ^^^^^^^^^^^^^^^^^^^^^^^^^^^^^^^^^^^^^^^^^^^^^^^^^^^^^^^^
  File "/home/hk-project-sustainebot/bm3844/miniconda3/envs/roboG_train/lib/python3.12/site-packages/torch/distributed/launcher/api.py", line 277, in launch_agent
    raise ChildFailedError(
torch.distributed.elastic.multiprocessing.errors.ChildFailedError: 
============================================================
/home/hk-project-sustainebot/bm3844/code/LLaMA-Factory-RoboG-v2/src/llamafactory/launcher.py FAILED
------------------------------------------------------------
Failures:
[1]:
  time      : 2025-10-22_01:08:51
  host      : hkn0523.localdomain
  rank      : 1 (local_rank: 1)
  exitcode  : 1 (pid: 3675907)
  error_file: <N/A>
  traceback : To enable traceback see: https://pytorch.org/docs/stable/elastic/errors.html
[2]:
  time      : 2025-10-22_01:08:51
  host      : hkn0523.localdomain
  rank      : 2 (local_rank: 2)
  exitcode  : 1 (pid: 3675908)
  error_file: <N/A>
  traceback : To enable traceback see: https://pytorch.org/docs/stable/elastic/errors.html
[3]:
  time      : 2025-10-22_01:08:51
  host      : hkn0523.localdomain
  rank      : 3 (local_rank: 3)
  exitcode  : 1 (pid: 3675909)
  error_file: <N/A>
  traceback : To enable traceback see: https://pytorch.org/docs/stable/elastic/errors.html
------------------------------------------------------------
Root Cause (first observed failure):
[0]:
  time      : 2025-10-22_01:08:51
  host      : hkn0523.localdomain
  rank      : 0 (local_rank: 0)
  exitcode  : 1 (pid: 3675906)
  error_file: <N/A>
  traceback : To enable traceback see: https://pytorch.org/docs/stable/elastic/errors.html
============================================================
Traceback (most recent call last):
  File "<frozen runpy>", line 198, in _run_module_as_main
  File "<frozen runpy>", line 88, in _run_code
  File "/home/hk-project-sustainebot/bm3844/code/LLaMA-Factory-RoboG-v2/src/llamafactory/cli.py", line 31, in <module>
    main()
  File "/home/hk-project-sustainebot/bm3844/code/LLaMA-Factory-RoboG-v2/src/llamafactory/cli.py", line 24, in main
    launcher.launch()
  File "/home/hk-project-sustainebot/bm3844/code/LLaMA-Factory-RoboG-v2/src/llamafactory/launcher.py", line 110, in launch
    process = subprocess.run(
              ^^^^^^^^^^^^^^^
  File "/home/hk-project-sustainebot/bm3844/miniconda3/envs/roboG_train/lib/python3.12/subprocess.py", line 571, in run
    raise CalledProcessError(retcode, process.args,
subprocess.CalledProcessError: Command '['torchrun', '--nnodes', '1', '--node_rank', '0', '--nproc_per_node', '4', '--master_addr', '127.0.0.1', '--master_port', '37029', '/home/hk-project-sustainebot/bm3844/code/LLaMA-Factory-RoboG-v2/src/llamafactory/launcher.py']' returned non-zero exit status 1.
srun: error: hkn0523: task 0: Exited with exit code 1
